<robot name="simple_robot">
  <link name="base_link">
    <visual>
      <geometry>
        <cylinder length="0.01" radius="0.2"/>
      </geometry>
      <origin rpy="0 0 0" xyz="0 0 0"/>
      <material name="generic">
        <color rgba="1 1 0 1"/>
      </material>
    </visual>
  </link>
  <joint name="joint1" type="revolute">
    <parent link="base_link"/>
    <child link="link1"/>
    <origin xyz="0 0 0.0"/>
    <axis xyz="0 0 1"/>
    <limit effort="300" velocity="0.1" lower="-3.14" upper="3.14"/>
    <dynamics damping="50" friction="1"/>
  </joint>
  <link name="link1">
    <visual>
      <geometry>
        <cylinder length="0.4" radius="0.04"/>
      </geometry>
      <origin rpy="0 0 0" xyz="0 0 0.2"/>
      <material name="generic_2">
        <color rgba="0 0 1 1"/>
      </material>
    </visual>
  </link>
  
  <joint name="joint2" type="revolute">
    <parent link="link1"/>
    <child link="link2"/>
    <origin xyz="0 0 0.4"/>
    <axis xyz="0 -1 0"/>
    <limit effort="300" velocity="0.1" lower="-3.14" upper="3.14"/>
    <dynamics damping="50" friction="1"/>
  </joint>
  <link name="link2">
    <visual>
      <geometry>
        <cylinder length="0.3" radius="0.04"/>
      </geometry>
      <origin rpy="0 1.5708 0" xyz="0.15 0 0"/>
      <material name="generic_3">
        <color rgba="0 1 0 1"/>
      </material>
    </visual>
  </link>
  <joint name="joint3" type="revolute">
    <parent link="link2"/>
    <child link="link3"/>
    <origin xyz="0.3 0 0"/>
    <axis xyz="0 -1 0"/>
    <limit effort="300" velocity="0.1" lower="-3.14" upper="3.14"/>
    <dynamics damping="50" friction="1"/>
  </joint>
  <link name="link3">
    <visual>
      <geometry>
        <cylinder length="0.2" radius="0.04"/>
      </geometry>
      <origin rpy="0 1.5708 0" xyz="0.1 0 0"/>
      <material name="generic_4">
        <color rgba="0 1 1 1"/>
      </material>
    </visual>
  </link>
</robot>
